<?xml version="1.0" encoding="UTF-8"?>
<testng-results skipped="0" failed="10" ignored="0" total="20" passed="10">
  <reporter-output>
    <line>
      <![CDATA[[INFO] : Assertion Passed : Rotation is working fine]]>
    </line>
    <line>
      <![CDATA[[INFO] : Assertion Passed : Add New Entry functionality is working fine]]>
    </line>
    <line>
      <![CDATA[[INFO] : Assertion Passed : Not able to add duplicate number]]>
    </line>
    <line>
      <![CDATA[[INFO] : Assertion Passed : Able to increase collection capacity]]>
    </line>
    <line>
      <![CDATA[[INFO] : Assertion Passed : Can handle remove parameter if collection is empty]]>
    </line>
    <line>
      <![CDATA[[INFO] : Assertion Passed : Collection length is correct]]>
    </line>
    <line>
      <![CDATA[[INFO] : Assertion Passed : Function returns position of entry in collection]]>
    </line>
    <line>
      <![CDATA[[INFO] : Assertion Passed : Function returns -1 if entry is not present]]>
    </line>
    <line>
      <![CDATA[[INFO] : Assertion Passed : Not able to add duplicate number]]>
    </line>
    <line>
      <![CDATA[[INFO] : Assertion Passed : Can handle remove parameter if collection is empty]]>
    </line>
  </reporter-output>
  <suite name="Surefire suite" duration-ms="46" started-at="2018-07-09T09:49:28Z" finished-at="2018-07-09T09:49:28Z">
    <groups>
    </groups>
    <test name="Surefire test" duration-ms="46" started-at="2018-07-09T09:49:28Z" finished-at="2018-07-09T09:49:28Z">
      <class name="testquestion2.Test_MyCollection">
        <test-method status="FAIL" signature="Test10_Rotate_Array()[pri:0, instance:testquestion2.Test_MyCollection@445b84c0]" name="Test10_Rotate_Array" duration-ms="1" started-at="2018-07-09T09:49:28Z" description="Left Rotation Collection Functionality" finished-at="2018-07-09T09:49:28Z">
          <exception class="java.lang.AssertionError">
            <message>
              <![CDATA[expected [{Is, Always, A Fun., Sometimes, Automation, Testing}] but found [question2.MyCollection@54a097cc]]]>
            </message>
            <full-stacktrace>
              <![CDATA[java.lang.AssertionError: expected [{Is, Always, A Fun., Sometimes, Automation, Testing}] but found [question2.MyCollection@54a097cc]
at org.testng.Assert.fail(Assert.java:96)
at org.testng.Assert.failNotEquals(Assert.java:776)
at org.testng.Assert.assertEqualsImpl(Assert.java:137)
at org.testng.Assert.assertEquals(Assert.java:118)
at org.testng.Assert.assertEquals(Assert.java:453)
at org.testng.Assert.assertEquals(Assert.java:463)
at testquestion2.Test_MyCollection.Test10_Rotate_Array(Test_MyCollection.java:94)
at sun.reflect.NativeMethodAccessorImpl.invoke0(Native Method)
at sun.reflect.NativeMethodAccessorImpl.invoke(NativeMethodAccessorImpl.java:62)
at sun.reflect.DelegatingMethodAccessorImpl.invoke(DelegatingMethodAccessorImpl.java:43)
at java.lang.reflect.Method.invoke(Method.java:498)
at org.testng.internal.MethodInvocationHelper.invokeMethod(MethodInvocationHelper.java:124)
at org.testng.internal.Invoker.invokeMethod(Invoker.java:583)
at org.testng.internal.Invoker.invokeTestMethod(Invoker.java:719)
at org.testng.internal.Invoker.invokeTestMethods(Invoker.java:989)
at org.testng.internal.TestMethodWorker.invokeTestMethods(TestMethodWorker.java:125)
at org.testng.internal.TestMethodWorker.run(TestMethodWorker.java:109)
at org.testng.TestRunner.privateRun(TestRunner.java:648)
at org.testng.TestRunner.run(TestRunner.java:505)
at org.testng.SuiteRunner.runTest(SuiteRunner.java:455)
at org.testng.SuiteRunner.runSequentially(SuiteRunner.java:450)
at org.testng.SuiteRunner.privateRun(SuiteRunner.java:415)
at org.testng.SuiteRunner.run(SuiteRunner.java:364)
at org.testng.SuiteRunnerWorker.runSuite(SuiteRunnerWorker.java:52)
at org.testng.SuiteRunnerWorker.run(SuiteRunnerWorker.java:84)
at org.testng.TestNG.runSuitesSequentially(TestNG.java:1208)
at org.testng.TestNG.runSuitesLocally(TestNG.java:1137)
at org.testng.TestNG.runSuites(TestNG.java:1049)
at org.testng.TestNG.run(TestNG.java:1017)
at org.apache.maven.surefire.testng.TestNGExecutor.run(TestNGExecutor.java:115)
at org.apache.maven.surefire.testng.TestNGDirectoryTestSuite.executeMulti(TestNGDirectoryTestSuite.java:204)
at org.apache.maven.surefire.testng.TestNGDirectoryTestSuite.execute(TestNGDirectoryTestSuite.java:107)
at org.apache.maven.surefire.testng.TestNGProvider.invoke(TestNGProvider.java:112)
at org.apache.maven.surefire.booter.ForkedBooter.invokeProviderInSameClassLoader(ForkedBooter.java:200)
at org.apache.maven.surefire.booter.ForkedBooter.runSuitesInProcess(ForkedBooter.java:153)
at org.apache.maven.surefire.booter.ForkedBooter.main(ForkedBooter.java:103)
]]>
            </full-stacktrace>
          </exception> <!-- java.lang.AssertionError -->
          <reporter-output>
          </reporter-output>
        </test-method> <!-- Test10_Rotate_Array -->
        <test-method status="FAIL" signature="Test1_Able_To_Add_New_Entry_In_Collection()[pri:0, instance:testquestion2.Test_MyCollection@445b84c0]" name="Test1_Able_To_Add_New_Entry_In_Collection" duration-ms="0" started-at="2018-07-09T09:49:28Z" description="Check Add functionality" finished-at="2018-07-09T09:49:28Z">
          <exception class="java.lang.AssertionError">
            <message>
              <![CDATA[Assertion Failed : Not able to add number 5 in collection expected [true] but found [false]]]>
            </message>
            <full-stacktrace>
              <![CDATA[java.lang.AssertionError: Assertion Failed : Not able to add number 5 in collection expected [true] but found [false]
at org.testng.Assert.fail(Assert.java:96)
at org.testng.Assert.failNotEquals(Assert.java:776)
at org.testng.Assert.assertTrue(Assert.java:44)
at testquestion2.Test_MyCollection.Test1_Able_To_Add_New_Entry_In_Collection(Test_MyCollection.java:16)
at sun.reflect.NativeMethodAccessorImpl.invoke0(Native Method)
at sun.reflect.NativeMethodAccessorImpl.invoke(NativeMethodAccessorImpl.java:62)
at sun.reflect.DelegatingMethodAccessorImpl.invoke(DelegatingMethodAccessorImpl.java:43)
at java.lang.reflect.Method.invoke(Method.java:498)
at org.testng.internal.MethodInvocationHelper.invokeMethod(MethodInvocationHelper.java:124)
at org.testng.internal.Invoker.invokeMethod(Invoker.java:583)
at org.testng.internal.Invoker.invokeTestMethod(Invoker.java:719)
at org.testng.internal.Invoker.invokeTestMethods(Invoker.java:989)
at org.testng.internal.TestMethodWorker.invokeTestMethods(TestMethodWorker.java:125)
at org.testng.internal.TestMethodWorker.run(TestMethodWorker.java:109)
at org.testng.TestRunner.privateRun(TestRunner.java:648)
at org.testng.TestRunner.run(TestRunner.java:505)
at org.testng.SuiteRunner.runTest(SuiteRunner.java:455)
at org.testng.SuiteRunner.runSequentially(SuiteRunner.java:450)
at org.testng.SuiteRunner.privateRun(SuiteRunner.java:415)
at org.testng.SuiteRunner.run(SuiteRunner.java:364)
at org.testng.SuiteRunnerWorker.runSuite(SuiteRunnerWorker.java:52)
at org.testng.SuiteRunnerWorker.run(SuiteRunnerWorker.java:84)
at org.testng.TestNG.runSuitesSequentially(TestNG.java:1208)
at org.testng.TestNG.runSuitesLocally(TestNG.java:1137)
at org.testng.TestNG.runSuites(TestNG.java:1049)
at org.testng.TestNG.run(TestNG.java:1017)
at org.apache.maven.surefire.testng.TestNGExecutor.run(TestNGExecutor.java:115)
at org.apache.maven.surefire.testng.TestNGDirectoryTestSuite.executeMulti(TestNGDirectoryTestSuite.java:204)
at org.apache.maven.surefire.testng.TestNGDirectoryTestSuite.execute(TestNGDirectoryTestSuite.java:107)
at org.apache.maven.surefire.testng.TestNGProvider.invoke(TestNGProvider.java:112)
at org.apache.maven.surefire.booter.ForkedBooter.invokeProviderInSameClassLoader(ForkedBooter.java:200)
at org.apache.maven.surefire.booter.ForkedBooter.runSuitesInProcess(ForkedBooter.java:153)
at org.apache.maven.surefire.booter.ForkedBooter.main(ForkedBooter.java:103)
]]>
            </full-stacktrace>
          </exception> <!-- java.lang.AssertionError -->
          <reporter-output>
          </reporter-output>
        </test-method> <!-- Test1_Able_To_Add_New_Entry_In_Collection -->
        <test-method status="PASS" signature="Test2_Duplicate_Entry_In_Collection()[pri:0, instance:testquestion2.Test_MyCollection@445b84c0]" name="Test2_Duplicate_Entry_In_Collection" duration-ms="0" started-at="2018-07-09T09:49:28Z" description="Check Add functionality" finished-at="2018-07-09T09:49:28Z">
          <reporter-output>
            <line>
              <![CDATA[[INFO] : Assertion Passed : Not able to add duplicate number]]>
            </line>
          </reporter-output>
        </test-method> <!-- Test2_Duplicate_Entry_In_Collection -->
        <test-method status="FAIL" signature="Test4_DoubleCapacity()[pri:0, instance:testquestion2.Test_MyCollection@445b84c0]" name="Test4_DoubleCapacity" duration-ms="1" started-at="2018-07-09T09:49:28Z" description="Check Overflow Collection" finished-at="2018-07-09T09:49:28Z">
          <exception class="java.lang.AssertionError">
            <message>
              <![CDATA[Assertion Failed : Not able to add number in collection once it get fulled expected [{4,5,-4,-5,6}] but found [question2.MyCollection@2096442d]]]>
            </message>
            <full-stacktrace>
              <![CDATA[java.lang.AssertionError: Assertion Failed : Not able to add number in collection once it get fulled expected [{4,5,-4,-5,6}] but found [question2.MyCollection@2096442d]
at org.testng.Assert.fail(Assert.java:96)
at org.testng.Assert.failNotEquals(Assert.java:776)
at org.testng.Assert.assertEqualsImpl(Assert.java:137)
at org.testng.Assert.assertEquals(Assert.java:118)
at org.testng.Assert.assertEquals(Assert.java:453)
at testquestion2.Test_MyCollection.Test4_DoubleCapacity(Test_MyCollection.java:41)
at sun.reflect.NativeMethodAccessorImpl.invoke0(Native Method)
at sun.reflect.NativeMethodAccessorImpl.invoke(NativeMethodAccessorImpl.java:62)
at sun.reflect.DelegatingMethodAccessorImpl.invoke(DelegatingMethodAccessorImpl.java:43)
at java.lang.reflect.Method.invoke(Method.java:498)
at org.testng.internal.MethodInvocationHelper.invokeMethod(MethodInvocationHelper.java:124)
at org.testng.internal.Invoker.invokeMethod(Invoker.java:583)
at org.testng.internal.Invoker.invokeTestMethod(Invoker.java:719)
at org.testng.internal.Invoker.invokeTestMethods(Invoker.java:989)
at org.testng.internal.TestMethodWorker.invokeTestMethods(TestMethodWorker.java:125)
at org.testng.internal.TestMethodWorker.run(TestMethodWorker.java:109)
at org.testng.TestRunner.privateRun(TestRunner.java:648)
at org.testng.TestRunner.run(TestRunner.java:505)
at org.testng.SuiteRunner.runTest(SuiteRunner.java:455)
at org.testng.SuiteRunner.runSequentially(SuiteRunner.java:450)
at org.testng.SuiteRunner.privateRun(SuiteRunner.java:415)
at org.testng.SuiteRunner.run(SuiteRunner.java:364)
at org.testng.SuiteRunnerWorker.runSuite(SuiteRunnerWorker.java:52)
at org.testng.SuiteRunnerWorker.run(SuiteRunnerWorker.java:84)
at org.testng.TestNG.runSuitesSequentially(TestNG.java:1208)
at org.testng.TestNG.runSuitesLocally(TestNG.java:1137)
at org.testng.TestNG.runSuites(TestNG.java:1049)
at org.testng.TestNG.run(TestNG.java:1017)
at org.apache.maven.surefire.testng.TestNGExecutor.run(TestNGExecutor.java:115)
at org.apache.maven.surefire.testng.TestNGDirectoryTestSuite.executeMulti(TestNGDirectoryTestSuite.java:204)
at org.apache.maven.surefire.testng.TestNGDirectoryTestSuite.execute(TestNGDirectoryTestSuite.java:107)
at org.apache.maven.surefire.testng.TestNGProvider.invoke(TestNGProvider.java:112)
at org.apache.maven.surefire.booter.ForkedBooter.invokeProviderInSameClassLoader(ForkedBooter.java:200)
at org.apache.maven.surefire.booter.ForkedBooter.runSuitesInProcess(ForkedBooter.java:153)
at org.apache.maven.surefire.booter.ForkedBooter.main(ForkedBooter.java:103)
]]>
            </full-stacktrace>
          </exception> <!-- java.lang.AssertionError -->
          <reporter-output>
          </reporter-output>
        </test-method> <!-- Test4_DoubleCapacity -->
        <test-method status="FAIL" signature="Test3_Get_Collection_Functionality()[pri:0, instance:testquestion2.Test_MyCollection@445b84c0]" name="Test3_Get_Collection_Functionality" duration-ms="0" started-at="2018-07-09T09:49:28Z" description="Check toString function" finished-at="2018-07-09T09:49:28Z">
          <exception class="java.lang.AssertionError">
            <message>
              <![CDATA[Assertion Failed : Not able to read collection expected [{}] but found [question2.MyCollection@735b478]]]>
            </message>
            <full-stacktrace>
              <![CDATA[java.lang.AssertionError: Assertion Failed : Not able to read collection expected [{}] but found [question2.MyCollection@735b478]
at org.testng.Assert.fail(Assert.java:96)
at org.testng.Assert.failNotEquals(Assert.java:776)
at org.testng.Assert.assertEqualsImpl(Assert.java:137)
at org.testng.Assert.assertEquals(Assert.java:118)
at org.testng.Assert.assertEquals(Assert.java:453)
at testquestion2.Test_MyCollection.Test3_Get_Collection_Functionality(Test_MyCollection.java:32)
at sun.reflect.NativeMethodAccessorImpl.invoke0(Native Method)
at sun.reflect.NativeMethodAccessorImpl.invoke(NativeMethodAccessorImpl.java:62)
at sun.reflect.DelegatingMethodAccessorImpl.invoke(DelegatingMethodAccessorImpl.java:43)
at java.lang.reflect.Method.invoke(Method.java:498)
at org.testng.internal.MethodInvocationHelper.invokeMethod(MethodInvocationHelper.java:124)
at org.testng.internal.Invoker.invokeMethod(Invoker.java:583)
at org.testng.internal.Invoker.invokeTestMethod(Invoker.java:719)
at org.testng.internal.Invoker.invokeTestMethods(Invoker.java:989)
at org.testng.internal.TestMethodWorker.invokeTestMethods(TestMethodWorker.java:125)
at org.testng.internal.TestMethodWorker.run(TestMethodWorker.java:109)
at org.testng.TestRunner.privateRun(TestRunner.java:648)
at org.testng.TestRunner.run(TestRunner.java:505)
at org.testng.SuiteRunner.runTest(SuiteRunner.java:455)
at org.testng.SuiteRunner.runSequentially(SuiteRunner.java:450)
at org.testng.SuiteRunner.privateRun(SuiteRunner.java:415)
at org.testng.SuiteRunner.run(SuiteRunner.java:364)
at org.testng.SuiteRunnerWorker.runSuite(SuiteRunnerWorker.java:52)
at org.testng.SuiteRunnerWorker.run(SuiteRunnerWorker.java:84)
at org.testng.TestNG.runSuitesSequentially(TestNG.java:1208)
at org.testng.TestNG.runSuitesLocally(TestNG.java:1137)
at org.testng.TestNG.runSuites(TestNG.java:1049)
at org.testng.TestNG.run(TestNG.java:1017)
at org.apache.maven.surefire.testng.TestNGExecutor.run(TestNGExecutor.java:115)
at org.apache.maven.surefire.testng.TestNGDirectoryTestSuite.executeMulti(TestNGDirectoryTestSuite.java:204)
at org.apache.maven.surefire.testng.TestNGDirectoryTestSuite.execute(TestNGDirectoryTestSuite.java:107)
at org.apache.maven.surefire.testng.TestNGProvider.invoke(TestNGProvider.java:112)
at org.apache.maven.surefire.booter.ForkedBooter.invokeProviderInSameClassLoader(ForkedBooter.java:200)
at org.apache.maven.surefire.booter.ForkedBooter.runSuitesInProcess(ForkedBooter.java:153)
at org.apache.maven.surefire.booter.ForkedBooter.main(ForkedBooter.java:103)
]]>
            </full-stacktrace>
          </exception> <!-- java.lang.AssertionError -->
          <reporter-output>
          </reporter-output>
        </test-method> <!-- Test3_Get_Collection_Functionality -->
        <test-method status="FAIL" signature="Test5_Remove_Functionality_If_Entry_Already_Present()[pri:0, instance:testquestion2.Test_MyCollection@445b84c0]" name="Test5_Remove_Functionality_If_Entry_Already_Present" duration-ms="0" started-at="2018-07-09T09:49:28Z" description="Check remove functionality" finished-at="2018-07-09T09:49:28Z">
          <exception class="java.lang.AssertionError">
            <message>
              <![CDATA[Assetion Failed : Not Able to delete entry from collection expected [true] but found [false]]]>
            </message>
            <full-stacktrace>
              <![CDATA[java.lang.AssertionError: Assetion Failed : Not Able to delete entry from collection expected [true] but found [false]
at org.testng.Assert.fail(Assert.java:96)
at org.testng.Assert.failNotEquals(Assert.java:776)
at org.testng.Assert.assertTrue(Assert.java:44)
at testquestion2.Test_MyCollection.Test5_Remove_Functionality_If_Entry_Already_Present(Test_MyCollection.java:50)
at sun.reflect.NativeMethodAccessorImpl.invoke0(Native Method)
at sun.reflect.NativeMethodAccessorImpl.invoke(NativeMethodAccessorImpl.java:62)
at sun.reflect.DelegatingMethodAccessorImpl.invoke(DelegatingMethodAccessorImpl.java:43)
at java.lang.reflect.Method.invoke(Method.java:498)
at org.testng.internal.MethodInvocationHelper.invokeMethod(MethodInvocationHelper.java:124)
at org.testng.internal.Invoker.invokeMethod(Invoker.java:583)
at org.testng.internal.Invoker.invokeTestMethod(Invoker.java:719)
at org.testng.internal.Invoker.invokeTestMethods(Invoker.java:989)
at org.testng.internal.TestMethodWorker.invokeTestMethods(TestMethodWorker.java:125)
at org.testng.internal.TestMethodWorker.run(TestMethodWorker.java:109)
at org.testng.TestRunner.privateRun(TestRunner.java:648)
at org.testng.TestRunner.run(TestRunner.java:505)
at org.testng.SuiteRunner.runTest(SuiteRunner.java:455)
at org.testng.SuiteRunner.runSequentially(SuiteRunner.java:450)
at org.testng.SuiteRunner.privateRun(SuiteRunner.java:415)
at org.testng.SuiteRunner.run(SuiteRunner.java:364)
at org.testng.SuiteRunnerWorker.runSuite(SuiteRunnerWorker.java:52)
at org.testng.SuiteRunnerWorker.run(SuiteRunnerWorker.java:84)
at org.testng.TestNG.runSuitesSequentially(TestNG.java:1208)
at org.testng.TestNG.runSuitesLocally(TestNG.java:1137)
at org.testng.TestNG.runSuites(TestNG.java:1049)
at org.testng.TestNG.run(TestNG.java:1017)
at org.apache.maven.surefire.testng.TestNGExecutor.run(TestNGExecutor.java:115)
at org.apache.maven.surefire.testng.TestNGDirectoryTestSuite.executeMulti(TestNGDirectoryTestSuite.java:204)
at org.apache.maven.surefire.testng.TestNGDirectoryTestSuite.execute(TestNGDirectoryTestSuite.java:107)
at org.apache.maven.surefire.testng.TestNGProvider.invoke(TestNGProvider.java:112)
at org.apache.maven.surefire.booter.ForkedBooter.invokeProviderInSameClassLoader(ForkedBooter.java:200)
at org.apache.maven.surefire.booter.ForkedBooter.runSuitesInProcess(ForkedBooter.java:153)
at org.apache.maven.surefire.booter.ForkedBooter.main(ForkedBooter.java:103)
]]>
            </full-stacktrace>
          </exception> <!-- java.lang.AssertionError -->
          <reporter-output>
          </reporter-output>
        </test-method> <!-- Test5_Remove_Functionality_If_Entry_Already_Present -->
        <test-method status="FAIL" signature="Test7_Collection_Length_Functionality()[pri:0, instance:testquestion2.Test_MyCollection@445b84c0]" name="Test7_Collection_Length_Functionality" duration-ms="0" started-at="2018-07-09T09:49:28Z" description="Size of Collection" finished-at="2018-07-09T09:49:28Z">
          <exception class="java.lang.AssertionError">
            <message>
              <![CDATA[expected [6] but found [0]]]>
            </message>
            <full-stacktrace>
              <![CDATA[java.lang.AssertionError: expected [6] but found [0]
at org.testng.Assert.fail(Assert.java:96)
at org.testng.Assert.failNotEquals(Assert.java:776)
at org.testng.Assert.assertEqualsImpl(Assert.java:137)
at org.testng.Assert.assertEquals(Assert.java:118)
at org.testng.Assert.assertEquals(Assert.java:652)
at org.testng.Assert.assertEquals(Assert.java:662)
at testquestion2.Test_MyCollection.Test7_Collection_Length_Functionality(Test_MyCollection.java:66)
at sun.reflect.NativeMethodAccessorImpl.invoke0(Native Method)
at sun.reflect.NativeMethodAccessorImpl.invoke(NativeMethodAccessorImpl.java:62)
at sun.reflect.DelegatingMethodAccessorImpl.invoke(DelegatingMethodAccessorImpl.java:43)
at java.lang.reflect.Method.invoke(Method.java:498)
at org.testng.internal.MethodInvocationHelper.invokeMethod(MethodInvocationHelper.java:124)
at org.testng.internal.Invoker.invokeMethod(Invoker.java:583)
at org.testng.internal.Invoker.invokeTestMethod(Invoker.java:719)
at org.testng.internal.Invoker.invokeTestMethods(Invoker.java:989)
at org.testng.internal.TestMethodWorker.invokeTestMethods(TestMethodWorker.java:125)
at org.testng.internal.TestMethodWorker.run(TestMethodWorker.java:109)
at org.testng.TestRunner.privateRun(TestRunner.java:648)
at org.testng.TestRunner.run(TestRunner.java:505)
at org.testng.SuiteRunner.runTest(SuiteRunner.java:455)
at org.testng.SuiteRunner.runSequentially(SuiteRunner.java:450)
at org.testng.SuiteRunner.privateRun(SuiteRunner.java:415)
at org.testng.SuiteRunner.run(SuiteRunner.java:364)
at org.testng.SuiteRunnerWorker.runSuite(SuiteRunnerWorker.java:52)
at org.testng.SuiteRunnerWorker.run(SuiteRunnerWorker.java:84)
at org.testng.TestNG.runSuitesSequentially(TestNG.java:1208)
at org.testng.TestNG.runSuitesLocally(TestNG.java:1137)
at org.testng.TestNG.runSuites(TestNG.java:1049)
at org.testng.TestNG.run(TestNG.java:1017)
at org.apache.maven.surefire.testng.TestNGExecutor.run(TestNGExecutor.java:115)
at org.apache.maven.surefire.testng.TestNGDirectoryTestSuite.executeMulti(TestNGDirectoryTestSuite.java:204)
at org.apache.maven.surefire.testng.TestNGDirectoryTestSuite.execute(TestNGDirectoryTestSuite.java:107)
at org.apache.maven.surefire.testng.TestNGProvider.invoke(TestNGProvider.java:112)
at org.apache.maven.surefire.booter.ForkedBooter.invokeProviderInSameClassLoader(ForkedBooter.java:200)
at org.apache.maven.surefire.booter.ForkedBooter.runSuitesInProcess(ForkedBooter.java:153)
at org.apache.maven.surefire.booter.ForkedBooter.main(ForkedBooter.java:103)
]]>
            </full-stacktrace>
          </exception> <!-- java.lang.AssertionError -->
          <reporter-output>
          </reporter-output>
        </test-method> <!-- Test7_Collection_Length_Functionality -->
        <test-method status="PASS" signature="Test6_Remove_Functionality_If_Collection_Is_Empty()[pri:0, instance:testquestion2.Test_MyCollection@445b84c0]" name="Test6_Remove_Functionality_If_Collection_Is_Empty" duration-ms="0" started-at="2018-07-09T09:49:28Z" description="Check remove functionality" finished-at="2018-07-09T09:49:28Z">
          <reporter-output>
            <line>
              <![CDATA[[INFO] : Assertion Passed : Can handle remove parameter if collection is empty]]>
            </line>
          </reporter-output>
        </test-method> <!-- Test6_Remove_Functionality_If_Collection_Is_Empty -->
        <test-method status="FAIL" signature="Test8_Search_Functionality_If_Enrty_Exists()[pri:0, instance:testquestion2.Test_MyCollection@445b84c0]" name="Test8_Search_Functionality_If_Enrty_Exists" duration-ms="0" started-at="2018-07-09T09:49:28Z" description="Search Functionality" finished-at="2018-07-09T09:49:28Z">
          <exception class="java.lang.AssertionError">
            <message>
              <![CDATA[expected [1] but found [0]]]>
            </message>
            <full-stacktrace>
              <![CDATA[java.lang.AssertionError: expected [1] but found [0]
at org.testng.Assert.fail(Assert.java:96)
at org.testng.Assert.failNotEquals(Assert.java:776)
at org.testng.Assert.assertEqualsImpl(Assert.java:137)
at org.testng.Assert.assertEquals(Assert.java:118)
at org.testng.Assert.assertEquals(Assert.java:652)
at org.testng.Assert.assertEquals(Assert.java:662)
at testquestion2.Test_MyCollection.Test8_Search_Functionality_If_Enrty_Exists(Test_MyCollection.java:75)
at sun.reflect.NativeMethodAccessorImpl.invoke0(Native Method)
at sun.reflect.NativeMethodAccessorImpl.invoke(NativeMethodAccessorImpl.java:62)
at sun.reflect.DelegatingMethodAccessorImpl.invoke(DelegatingMethodAccessorImpl.java:43)
at java.lang.reflect.Method.invoke(Method.java:498)
at org.testng.internal.MethodInvocationHelper.invokeMethod(MethodInvocationHelper.java:124)
at org.testng.internal.Invoker.invokeMethod(Invoker.java:583)
at org.testng.internal.Invoker.invokeTestMethod(Invoker.java:719)
at org.testng.internal.Invoker.invokeTestMethods(Invoker.java:989)
at org.testng.internal.TestMethodWorker.invokeTestMethods(TestMethodWorker.java:125)
at org.testng.internal.TestMethodWorker.run(TestMethodWorker.java:109)
at org.testng.TestRunner.privateRun(TestRunner.java:648)
at org.testng.TestRunner.run(TestRunner.java:505)
at org.testng.SuiteRunner.runTest(SuiteRunner.java:455)
at org.testng.SuiteRunner.runSequentially(SuiteRunner.java:450)
at org.testng.SuiteRunner.privateRun(SuiteRunner.java:415)
at org.testng.SuiteRunner.run(SuiteRunner.java:364)
at org.testng.SuiteRunnerWorker.runSuite(SuiteRunnerWorker.java:52)
at org.testng.SuiteRunnerWorker.run(SuiteRunnerWorker.java:84)
at org.testng.TestNG.runSuitesSequentially(TestNG.java:1208)
at org.testng.TestNG.runSuitesLocally(TestNG.java:1137)
at org.testng.TestNG.runSuites(TestNG.java:1049)
at org.testng.TestNG.run(TestNG.java:1017)
at org.apache.maven.surefire.testng.TestNGExecutor.run(TestNGExecutor.java:115)
at org.apache.maven.surefire.testng.TestNGDirectoryTestSuite.executeMulti(TestNGDirectoryTestSuite.java:204)
at org.apache.maven.surefire.testng.TestNGDirectoryTestSuite.execute(TestNGDirectoryTestSuite.java:107)
at org.apache.maven.surefire.testng.TestNGProvider.invoke(TestNGProvider.java:112)
at org.apache.maven.surefire.booter.ForkedBooter.invokeProviderInSameClassLoader(ForkedBooter.java:200)
at org.apache.maven.surefire.booter.ForkedBooter.runSuitesInProcess(ForkedBooter.java:153)
at org.apache.maven.surefire.booter.ForkedBooter.main(ForkedBooter.java:103)
]]>
            </full-stacktrace>
          </exception> <!-- java.lang.AssertionError -->
          <reporter-output>
          </reporter-output>
        </test-method> <!-- Test8_Search_Functionality_If_Enrty_Exists -->
        <test-method status="FAIL" signature="Test9_Search_Functionality_If_Enrty_Not_Exists()[pri:0, instance:testquestion2.Test_MyCollection@445b84c0]" name="Test9_Search_Functionality_If_Enrty_Not_Exists" duration-ms="0" started-at="2018-07-09T09:49:28Z" description="Search Functionality" finished-at="2018-07-09T09:49:28Z">
          <exception class="java.lang.AssertionError">
            <message>
              <![CDATA[expected [-1] but found [0]]]>
            </message>
            <full-stacktrace>
              <![CDATA[java.lang.AssertionError: expected [-1] but found [0]
at org.testng.Assert.fail(Assert.java:96)
at org.testng.Assert.failNotEquals(Assert.java:776)
at org.testng.Assert.assertEqualsImpl(Assert.java:137)
at org.testng.Assert.assertEquals(Assert.java:118)
at org.testng.Assert.assertEquals(Assert.java:652)
at org.testng.Assert.assertEquals(Assert.java:662)
at testquestion2.Test_MyCollection.Test9_Search_Functionality_If_Enrty_Not_Exists(Test_MyCollection.java:84)
at sun.reflect.NativeMethodAccessorImpl.invoke0(Native Method)
at sun.reflect.NativeMethodAccessorImpl.invoke(NativeMethodAccessorImpl.java:62)
at sun.reflect.DelegatingMethodAccessorImpl.invoke(DelegatingMethodAccessorImpl.java:43)
at java.lang.reflect.Method.invoke(Method.java:498)
at org.testng.internal.MethodInvocationHelper.invokeMethod(MethodInvocationHelper.java:124)
at org.testng.internal.Invoker.invokeMethod(Invoker.java:583)
at org.testng.internal.Invoker.invokeTestMethod(Invoker.java:719)
at org.testng.internal.Invoker.invokeTestMethods(Invoker.java:989)
at org.testng.internal.TestMethodWorker.invokeTestMethods(TestMethodWorker.java:125)
at org.testng.internal.TestMethodWorker.run(TestMethodWorker.java:109)
at org.testng.TestRunner.privateRun(TestRunner.java:648)
at org.testng.TestRunner.run(TestRunner.java:505)
at org.testng.SuiteRunner.runTest(SuiteRunner.java:455)
at org.testng.SuiteRunner.runSequentially(SuiteRunner.java:450)
at org.testng.SuiteRunner.privateRun(SuiteRunner.java:415)
at org.testng.SuiteRunner.run(SuiteRunner.java:364)
at org.testng.SuiteRunnerWorker.runSuite(SuiteRunnerWorker.java:52)
at org.testng.SuiteRunnerWorker.run(SuiteRunnerWorker.java:84)
at org.testng.TestNG.runSuitesSequentially(TestNG.java:1208)
at org.testng.TestNG.runSuitesLocally(TestNG.java:1137)
at org.testng.TestNG.runSuites(TestNG.java:1049)
at org.testng.TestNG.run(TestNG.java:1017)
at org.apache.maven.surefire.testng.TestNGExecutor.run(TestNGExecutor.java:115)
at org.apache.maven.surefire.testng.TestNGDirectoryTestSuite.executeMulti(TestNGDirectoryTestSuite.java:204)
at org.apache.maven.surefire.testng.TestNGDirectoryTestSuite.execute(TestNGDirectoryTestSuite.java:107)
at org.apache.maven.surefire.testng.TestNGProvider.invoke(TestNGProvider.java:112)
at org.apache.maven.surefire.booter.ForkedBooter.invokeProviderInSameClassLoader(ForkedBooter.java:200)
at org.apache.maven.surefire.booter.ForkedBooter.runSuitesInProcess(ForkedBooter.java:153)
at org.apache.maven.surefire.booter.ForkedBooter.main(ForkedBooter.java:103)
]]>
            </full-stacktrace>
          </exception> <!-- java.lang.AssertionError -->
          <reporter-output>
          </reporter-output>
        </test-method> <!-- Test9_Search_Functionality_If_Enrty_Not_Exists -->
      </class> <!-- testquestion2.Test_MyCollection -->
      <class name="testquestion1.Test_MyCollection">
        <test-method status="PASS" signature="Test10_Rotate_Array()[pri:0, instance:testquestion1.Test_MyCollection@61443d8f]" name="Test10_Rotate_Array" duration-ms="7" started-at="2018-07-09T09:49:28Z" description="Left Rotation Collection Functionality" finished-at="2018-07-09T09:49:28Z">
          <reporter-output>
            <line>
              <![CDATA[[INFO] : Assertion Passed : Rotation is working fine]]>
            </line>
          </reporter-output>
        </test-method> <!-- Test10_Rotate_Array -->
        <test-method status="PASS" signature="Test2_Duplicate_Entry_In_Collection()[pri:0, instance:testquestion1.Test_MyCollection@61443d8f]" name="Test2_Duplicate_Entry_In_Collection" duration-ms="0" started-at="2018-07-09T09:49:28Z" description="Check Add functionality" finished-at="2018-07-09T09:49:28Z">
          <reporter-output>
            <line>
              <![CDATA[[INFO] : Assertion Passed : Not able to add duplicate number]]>
            </line>
          </reporter-output>
        </test-method> <!-- Test2_Duplicate_Entry_In_Collection -->
        <test-method status="PASS" signature="Test1_Able_To_Add_New_Entry_In_Collection()[pri:0, instance:testquestion1.Test_MyCollection@61443d8f]" name="Test1_Able_To_Add_New_Entry_In_Collection" duration-ms="0" started-at="2018-07-09T09:49:28Z" description="Check Add functionality" finished-at="2018-07-09T09:49:28Z">
          <reporter-output>
            <line>
              <![CDATA[[INFO] : Assertion Passed : Add New Entry functionality is working fine]]>
            </line>
          </reporter-output>
        </test-method> <!-- Test1_Able_To_Add_New_Entry_In_Collection -->
        <test-method status="FAIL" signature="Test3_Get_Collection_Functionality()[pri:0, instance:testquestion1.Test_MyCollection@61443d8f]" name="Test3_Get_Collection_Functionality" duration-ms="0" started-at="2018-07-09T09:49:28Z" description="Check toString function" finished-at="2018-07-09T09:49:28Z">
          <exception class="java.lang.ArrayIndexOutOfBoundsException">
            <message>
              <![CDATA[-1]]>
            </message>
            <full-stacktrace>
              <![CDATA[java.lang.ArrayIndexOutOfBoundsException: -1
at question1.MyCollection.toString(MyCollection.java:113)
at testquestion1.Test_MyCollection.Test3_Get_Collection_Functionality(Test_MyCollection.java:32)
at sun.reflect.NativeMethodAccessorImpl.invoke0(Native Method)
at sun.reflect.NativeMethodAccessorImpl.invoke(NativeMethodAccessorImpl.java:62)
at sun.reflect.DelegatingMethodAccessorImpl.invoke(DelegatingMethodAccessorImpl.java:43)
at java.lang.reflect.Method.invoke(Method.java:498)
at org.testng.internal.MethodInvocationHelper.invokeMethod(MethodInvocationHelper.java:124)
at org.testng.internal.Invoker.invokeMethod(Invoker.java:583)
at org.testng.internal.Invoker.invokeTestMethod(Invoker.java:719)
at org.testng.internal.Invoker.invokeTestMethods(Invoker.java:989)
at org.testng.internal.TestMethodWorker.invokeTestMethods(TestMethodWorker.java:125)
at org.testng.internal.TestMethodWorker.run(TestMethodWorker.java:109)
at org.testng.TestRunner.privateRun(TestRunner.java:648)
at org.testng.TestRunner.run(TestRunner.java:505)
at org.testng.SuiteRunner.runTest(SuiteRunner.java:455)
at org.testng.SuiteRunner.runSequentially(SuiteRunner.java:450)
at org.testng.SuiteRunner.privateRun(SuiteRunner.java:415)
at org.testng.SuiteRunner.run(SuiteRunner.java:364)
at org.testng.SuiteRunnerWorker.runSuite(SuiteRunnerWorker.java:52)
at org.testng.SuiteRunnerWorker.run(SuiteRunnerWorker.java:84)
at org.testng.TestNG.runSuitesSequentially(TestNG.java:1208)
at org.testng.TestNG.runSuitesLocally(TestNG.java:1137)
at org.testng.TestNG.runSuites(TestNG.java:1049)
at org.testng.TestNG.run(TestNG.java:1017)
at org.apache.maven.surefire.testng.TestNGExecutor.run(TestNGExecutor.java:115)
at org.apache.maven.surefire.testng.TestNGDirectoryTestSuite.executeMulti(TestNGDirectoryTestSuite.java:204)
at org.apache.maven.surefire.testng.TestNGDirectoryTestSuite.execute(TestNGDirectoryTestSuite.java:107)
at org.apache.maven.surefire.testng.TestNGProvider.invoke(TestNGProvider.java:112)
at org.apache.maven.surefire.booter.ForkedBooter.invokeProviderInSameClassLoader(ForkedBooter.java:200)
at org.apache.maven.surefire.booter.ForkedBooter.runSuitesInProcess(ForkedBooter.java:153)
at org.apache.maven.surefire.booter.ForkedBooter.main(ForkedBooter.java:103)
]]>
            </full-stacktrace>
          </exception> <!-- java.lang.ArrayIndexOutOfBoundsException -->
          <reporter-output>
          </reporter-output>
        </test-method> <!-- Test3_Get_Collection_Functionality -->
        <test-method status="PASS" signature="Test4_DoubleCapacity()[pri:0, instance:testquestion1.Test_MyCollection@61443d8f]" name="Test4_DoubleCapacity" duration-ms="1" started-at="2018-07-09T09:49:28Z" description="Check Overflow Collection" finished-at="2018-07-09T09:49:28Z">
          <reporter-output>
            <line>
              <![CDATA[[INFO] : Assertion Passed : Able to increase collection capacity]]>
            </line>
          </reporter-output>
        </test-method> <!-- Test4_DoubleCapacity -->
        <test-method status="FAIL" signature="Test5_Remove_Functionality_If_Entry_Already_Present()[pri:0, instance:testquestion1.Test_MyCollection@61443d8f]" name="Test5_Remove_Functionality_If_Entry_Already_Present" duration-ms="0" started-at="2018-07-09T09:49:28Z" description="Check remove functionality" finished-at="2018-07-09T09:49:28Z">
          <exception class="java.lang.ArrayIndexOutOfBoundsException">
            <message>
              <![CDATA[12]]>
            </message>
            <full-stacktrace>
              <![CDATA[java.lang.ArrayIndexOutOfBoundsException: 12
at question1.MyCollection.remove(MyCollection.java:74)
at testquestion1.Test_MyCollection.Test5_Remove_Functionality_If_Entry_Already_Present(Test_MyCollection.java:50)
at sun.reflect.NativeMethodAccessorImpl.invoke0(Native Method)
at sun.reflect.NativeMethodAccessorImpl.invoke(NativeMethodAccessorImpl.java:62)
at sun.reflect.DelegatingMethodAccessorImpl.invoke(DelegatingMethodAccessorImpl.java:43)
at java.lang.reflect.Method.invoke(Method.java:498)
at org.testng.internal.MethodInvocationHelper.invokeMethod(MethodInvocationHelper.java:124)
at org.testng.internal.Invoker.invokeMethod(Invoker.java:583)
at org.testng.internal.Invoker.invokeTestMethod(Invoker.java:719)
at org.testng.internal.Invoker.invokeTestMethods(Invoker.java:989)
at org.testng.internal.TestMethodWorker.invokeTestMethods(TestMethodWorker.java:125)
at org.testng.internal.TestMethodWorker.run(TestMethodWorker.java:109)
at org.testng.TestRunner.privateRun(TestRunner.java:648)
at org.testng.TestRunner.run(TestRunner.java:505)
at org.testng.SuiteRunner.runTest(SuiteRunner.java:455)
at org.testng.SuiteRunner.runSequentially(SuiteRunner.java:450)
at org.testng.SuiteRunner.privateRun(SuiteRunner.java:415)
at org.testng.SuiteRunner.run(SuiteRunner.java:364)
at org.testng.SuiteRunnerWorker.runSuite(SuiteRunnerWorker.java:52)
at org.testng.SuiteRunnerWorker.run(SuiteRunnerWorker.java:84)
at org.testng.TestNG.runSuitesSequentially(TestNG.java:1208)
at org.testng.TestNG.runSuitesLocally(TestNG.java:1137)
at org.testng.TestNG.runSuites(TestNG.java:1049)
at org.testng.TestNG.run(TestNG.java:1017)
at org.apache.maven.surefire.testng.TestNGExecutor.run(TestNGExecutor.java:115)
at org.apache.maven.surefire.testng.TestNGDirectoryTestSuite.executeMulti(TestNGDirectoryTestSuite.java:204)
at org.apache.maven.surefire.testng.TestNGDirectoryTestSuite.execute(TestNGDirectoryTestSuite.java:107)
at org.apache.maven.surefire.testng.TestNGProvider.invoke(TestNGProvider.java:112)
at org.apache.maven.surefire.booter.ForkedBooter.invokeProviderInSameClassLoader(ForkedBooter.java:200)
at org.apache.maven.surefire.booter.ForkedBooter.runSuitesInProcess(ForkedBooter.java:153)
at org.apache.maven.surefire.booter.ForkedBooter.main(ForkedBooter.java:103)
]]>
            </full-stacktrace>
          </exception> <!-- java.lang.ArrayIndexOutOfBoundsException -->
          <reporter-output>
          </reporter-output>
        </test-method> <!-- Test5_Remove_Functionality_If_Entry_Already_Present -->
        <test-method status="PASS" signature="Test7_Collection_Length_Functionality()[pri:0, instance:testquestion1.Test_MyCollection@61443d8f]" name="Test7_Collection_Length_Functionality" duration-ms="0" started-at="2018-07-09T09:49:28Z" description="Size of Collection" finished-at="2018-07-09T09:49:28Z">
          <reporter-output>
            <line>
              <![CDATA[[INFO] : Assertion Passed : Collection length is correct]]>
            </line>
          </reporter-output>
        </test-method> <!-- Test7_Collection_Length_Functionality -->
        <test-method status="PASS" signature="Test6_Remove_Functionality_If_Collection_Is_Empty()[pri:0, instance:testquestion1.Test_MyCollection@61443d8f]" name="Test6_Remove_Functionality_If_Collection_Is_Empty" duration-ms="0" started-at="2018-07-09T09:49:28Z" description="Check remove functionality" finished-at="2018-07-09T09:49:28Z">
          <reporter-output>
            <line>
              <![CDATA[[INFO] : Assertion Passed : Can handle remove parameter if collection is empty]]>
            </line>
          </reporter-output>
        </test-method> <!-- Test6_Remove_Functionality_If_Collection_Is_Empty -->
        <test-method status="PASS" signature="Test9_Search_Functionality_If_Enrty_Not_Exists()[pri:0, instance:testquestion1.Test_MyCollection@61443d8f]" name="Test9_Search_Functionality_If_Enrty_Not_Exists" duration-ms="0" started-at="2018-07-09T09:49:28Z" description="Search Functionality" finished-at="2018-07-09T09:49:28Z">
          <reporter-output>
            <line>
              <![CDATA[[INFO] : Assertion Passed : Function returns -1 if entry is not present]]>
            </line>
          </reporter-output>
        </test-method> <!-- Test9_Search_Functionality_If_Enrty_Not_Exists -->
        <test-method status="PASS" signature="Test8_Search_Functionality_If_Enrty_Exists()[pri:0, instance:testquestion1.Test_MyCollection@61443d8f]" name="Test8_Search_Functionality_If_Enrty_Exists" duration-ms="0" started-at="2018-07-09T09:49:28Z" description="Search Functionality" finished-at="2018-07-09T09:49:28Z">
          <reporter-output>
            <line>
              <![CDATA[[INFO] : Assertion Passed : Function returns position of entry in collection]]>
            </line>
          </reporter-output>
        </test-method> <!-- Test8_Search_Functionality_If_Enrty_Exists -->
      </class> <!-- testquestion1.Test_MyCollection -->
    </test> <!-- Surefire test -->
  </suite> <!-- Surefire suite -->
</testng-results>
